<?xml version="1.0" encoding="utf-8"?>
<robot
name="my_robot">
<link
name="base_link_arm">
</link>

<joint name="fix0" type="fixed">
  <origin rpy="0.0 0.0 0.0" xyz="0.0 0.0 0.0"></origin>
  <parent link="base_link_arm"></parent>
  <child link="leg202_in"></child>
</joint>

    <!-- <?xml version="1.0" encoding="utf-8"?> -->
<!-- <robot name="hero_7dof_v2"> -->
  
  
  

  
  

  <link
  name="leg202_in">
  </link>
  <link
  name="leg202_gripper1_base">
    <inertial>
      <origin
        xyz="-7.1201E-05 0.00037469 0.034494"
        rpy="0 0 0" />
      <mass
        value="1.14" />
      <inertia
        ixx="0.00052757"
        ixy="4.0284E-07"
        ixz="-5.0575E-07"
        iyy="0.00020858"
        iyz="1.162E-07"
        izz="0.0007085" />
    </inertial>
    <visual>
      <origin
        xyz="0 0 0"
        rpy="0 0 0" />
      <geometry>
        <mesh
        filename="package://hero_ros2/meshes/hero_7dof_arm_v2/raw/collada/gripper1_base.dae" />
      </geometry>
    </visual>
    <collision>
      <isaac_sim>
        <attribute name="physics:approximation" value="sdf" />
      </isaac_sim>
      <origin
        xyz="0 0 0"
        rpy="0 0 0" />
      <geometry>
        <mesh
        filename="package://hero_ros2/meshes/hero_7dof_arm_v2/collision/gripper1_base.stl" />
      </geometry>
    </collision>
  </link>
  <joint
  name="leg202_root2base"
    type="fixed">
    <origin
      xyz="0 0 0.06"
    rpy="0 3.141592653589793 1.5707963267948966" />
    <parent
    link="leg202_in" />
    <child
    link="leg202_gripper1_base" />
  </joint>
  <link
  name="leg202_gripper1_jaw_left">
    <inertial>
      <origin
        xyz="0.041221 0.028338 0.031675"
        rpy="0 0 0" />
      <mass
        value="0.33" />
      <inertia
        ixx="0.00015197"
        ixy="-1.8396E-05"
        ixz="9.6283E-06"
        iyy="0.00010778"
        iyz="-3.1239E-06"
        izz="0.00017771" />
    </inertial>
    <visual>
      <origin
        xyz="0 0 0"
        rpy="0 0 0" />
      <geometry>
        <mesh
        filename="package://hero_ros2/meshes/hero_7dof_arm_v2/raw/collada/gripper1_jaw_left.dae" />
      </geometry>
    </visual>
    <collision>
      <isaac_sim>
        <attribute name="physics:approximation" value="sdf" />
      </isaac_sim>
      <origin
        xyz="0 0 0"
        rpy="0 0 0" />
      <geometry>
        <mesh
        filename="package://hero_ros2/meshes/hero_7dof_arm_v2/collision/gripper1_jaw_left.stl" />
      </geometry>
    </collision>
  </link>
  <joint
  name="leg202_grip1"
    type="prismatic">
    <origin
      xyz="-0.035 -0.067 0.05"
      rpy="0 0 0" />
    <parent
    link="leg202_gripper1_base" />
    <child
    link="leg202_gripper1_jaw_left" />
    <axis
      xyz="0 -1 0" />
    <limit
      lower="-0.05"
      upper="0.017"
      effort="9999"
      velocity="9999" />
    
    <isaac_sim>
      <attribute name="drive:linear:physics:maxForce" value="150000" />
      <attribute name="drive:linear:physics:damping" value="1000000.0"/>
      <attribute name="drive:linear:physics:stiffness" value="10000000.0"/>
    </isaac_sim>
  
  </joint>
  <link
  name="leg202_gripper1_jaw_right">
    <inertial>
      <origin
        xyz="0.042662 -0.018778 0.031675"
        rpy="0 0 0" />
      <mass
        value="0.33" />
      <inertia
        ixx="0.00010778"
        ixy="1.8396E-05"
        ixz="3.1239E-06"
        iyy="0.00015197"
        iyz="9.6283E-06"
        izz="0.00017771" />
    </inertial>
    <visual>
      <origin
        xyz="0 0 0"
        rpy="0 0 0" />
      <geometry>
        <mesh
        filename="package://hero_ros2/meshes/hero_7dof_arm_v2/raw/collada/gripper1_jaw_right.dae" />
      </geometry>
    </visual>
    <collision>
      <isaac_sim>
        <attribute name="physics:approximation" value="sdf" />
      </isaac_sim>
      <origin
        xyz="0 0 0"
        rpy="0 0 0" />
      <geometry>
        <mesh
        filename="package://hero_ros2/meshes/hero_7dof_arm_v2/collision/gripper1_jaw_right.stl" />
      </geometry>
    </collision>
  </link>
  <joint
  name="leg202_grip1bis"
    type="prismatic">
    <origin
      xyz="-0.025 -0.004 0.05"
      rpy="0 0 1.5708" />
    <parent
    link="leg202_gripper1_base" />
    <child
    link="leg202_gripper1_jaw_right" />
    <axis
      xyz="-1 0 0" />
    <limit
      lower="-0.05"
      upper="0.02"
      effort="9999"
      velocity="9999" />
    <mimic
    joint="leg202_grip1"
      multiplier="-1"
      offset="0" />
    
    <isaac_sim>
      <!-- Use low compliance mimic joint for the gripper -->
      <attribute name="physxMimicJoint:rotX:naturalFrequency" value="0.0" />
      <attribute name="physxMimicJoint:rotX:dampingRatio" value="0.005" />
    </isaac_sim>
  
  </joint>
  <link
  name="leg202_link1">
    <inertial>
      <origin
        xyz="9.4989E-05 0.025017 -0.056633"
        rpy="0 0 0" />
      <mass
        value="1.3" />
      <inertia
        ixx="0.00035389"
        ixy="-1.7567E-07"
        ixz="6.6517E-07"
        iyy="0.00040724"
        iyz="8.1435E-05"
        izz="0.00040084" />
    </inertial>
    <visual>
      <origin
        xyz="0 0 0"
        rpy="0 0 0" />
      <geometry>
        <mesh
        filename="package://hero_ros2/meshes/hero_7dof_arm_v2/raw/collada/link1.dae" />
      </geometry>
    </visual>
    <collision>
      <origin
        xyz="0 0 0"
        rpy="0 0 0" />
      <geometry>
        <mesh
        filename="package://hero_ros2/meshes/hero_7dof_arm_v2/raw/collada/link1.dae" />
      </geometry>
    </collision>
  </link>
  <joint
  name="leg202_joint1"
    type="continuous">
    <origin
      xyz="0 0 0.0035001"
    rpy="0 0 3.141592653589793" />
    <parent
    link="leg202_gripper1_base" />
    <child
    link="leg202_link1" />
    <axis
      xyz="0 0 -1" />
    <limit
      lower="-9999"
      upper="9999"
      effort="9999"
      velocity="0.2" />
  </joint>
  <link
  name="leg202_link2">
    <inertial>
      <origin
        xyz="-0.025016 9.5005E-05 -0.046633"
        rpy="0 0 0" />
      <mass
        value="1.3" />
      <inertia
        ixx="0.00040724"
        ixy="1.7604E-07"
        ixz="-8.1435E-05"
        iyy="0.00035389"
        iyz="6.6526E-07"
        izz="0.00040084" />
    </inertial>
    <visual>
      <origin
        xyz="0 0 0"
        rpy="0 0 0" />
      <geometry>
        <mesh
        filename="package://hero_ros2/meshes/hero_7dof_arm_v2/raw/collada/link2.dae" />
      </geometry>
    </visual>
    <collision>
      <origin
        xyz="0 0 0"
        rpy="0 0 0" />
      <geometry>
        <mesh
        filename="package://hero_ros2/meshes/hero_7dof_arm_v2/raw/collada/link2.dae" />
      </geometry>
    </collision>
  </link>
  <joint
  name="leg202_joint2"
    type="continuous">
    <origin
      xyz="0 0.0735 -0.067"
      rpy="1.5708 0 0" />
    <parent
    link="leg202_link1" />
    <child
    link="leg202_link2" />
    <axis
      xyz="0 0 -1" />
    <limit
      lower="-9999"
      upper="9999"
      effort="9999"
      velocity="0.2" />
  </joint>
  <link
  name="leg202_link3">
    <inertial>
      <origin
        xyz="0.22558 8.3334E-07 -0.043878"
        rpy="0 0 0" />
      <mass
        value="4.2" />
      <inertia
        ixx="0.0007977"
        ixy="1.899E-07"
        ixz="-7.9201E-05"
        iyy="0.013538"
        iyz="-2.0615E-09"
        izz="0.014042" />
    </inertial>
    <visual>
      <origin
        xyz="0 0 0"
        rpy="0 0 0" />
      <geometry>
        <mesh
        filename="package://hero_ros2/meshes/hero_7dof_arm_v2/raw/collada/link3.dae" />
      </geometry>
    </visual>
    <collision>
      <origin
        xyz="0 0 0"
        rpy="0 0 0" />
      <geometry>
        <mesh
        filename="package://hero_ros2/meshes/hero_7dof_arm_v2/raw/collada/link3.dae" />
      </geometry>
    </collision>
  </link>
  <joint
  name="leg202_joint3"
    type="continuous">
    <origin
      xyz="-0.0735 0 -0.057"
    rpy="-1.5708 1.5707963267948966 -1.5708" />
    <parent
    link="leg202_link2" />
    <child
    link="leg202_link3" />
    <axis
      xyz="0 0 -1" />
    <limit
      lower="-9999"
      upper="9999"
      effort="9999"
      velocity="0.2" />
  </joint>
  <link
  name="leg202_link4">
    <inertial>
      <origin
        xyz="0.19603 -5.9748E-05 -0.044745"
        rpy="0 0 0" />
      <mass
        value="4.2" />
      <inertia
        ixx="0.0007172"
        ixy="1.8275E-07"
        ixz="-8.0314E-07"
        iyy="0.011834"
        iyz="1.4123E-07"
        izz="0.012329" />
    </inertial>
    <visual>
      <origin
        xyz="0 0 0"
        rpy="0 0 0" />
      <geometry>
        <mesh
        filename="package://hero_ros2/meshes/hero_7dof_arm_v2/raw/collada/link4.dae" />
      </geometry>
    </visual>
    <collision>
      <origin
        xyz="0 0 0"
        rpy="0 0 0" />
      <geometry>
        <mesh
        filename="package://hero_ros2/meshes/hero_7dof_arm_v2/raw/collada/link4.dae" />
      </geometry>
    </collision>
  </link>
  <joint
  name="leg202_joint4"
    type="continuous">
    <origin
      xyz="0.4 0 0.0165"
    rpy="3.1416 0 -1.5707963267948966" />
    <parent
    link="leg202_link3" />
    <child
    link="leg202_link4" />
    <axis
      xyz="0 0 -1" />
    <limit
      lower="-9999"
      upper="9999"
      effort="9999"
      velocity="0.2" />
  </joint>
  <link
  name="leg202_link5">
    <inertial>
      <origin
        xyz="9.5006E-05 -0.010367 -0.041984"
        rpy="0 0 0" />
      <mass
        value="1.3" />
      <inertia
        ixx="0.00035389"
        ixy="-6.6526E-07"
        ixz="-1.7604E-07"
        iyy="0.00040084"
        iyz="-8.1435E-05"
        izz="0.00040724" />
    </inertial>
    <visual>
      <origin
        xyz="0 0 0"
        rpy="0 0 0" />
      <geometry>
        <mesh
        filename="package://hero_ros2/meshes/hero_7dof_arm_v2/raw/collada/link5.dae" />
      </geometry>
    </visual>
    <collision>
      <origin
        xyz="0 0 0"
        rpy="0 0 0" />
      <geometry>
        <mesh
        filename="package://hero_ros2/meshes/hero_7dof_arm_v2/raw/collada/link5.dae" />
      </geometry>
    </collision>
  </link>
  <joint
  name="leg202_joint5"
    type="continuous">
    <origin
      xyz="0.4 0 0.0065"
    rpy="-3.1416 0 -1.5707963267948966" />
    <parent
    link="leg202_link4" />
    <child
    link="leg202_link5" />
    <axis
      xyz="0 0 -1" />
    <limit
      lower="-9999"
      upper="9999"
      effort="9999"
      velocity="0.2" />
  </joint>
  <link
  name="leg202_link6">
    <inertial>
      <origin
        xyz="-0.00011294 0.01232 -0.059096"
        rpy="0 0 0" />
      <mass
        value="1.3" />
      <inertia
        ixx="0.00033037"
        ixy="-6.6518E-07"
        ixz="1.7602E-07"
        iyy="0.00037732"
        iyz="8.1435E-05"
        izz="0.00036156" />
    </inertial>
    <visual>
      <origin
        xyz="0 0 0"
        rpy="0 0 0" />
      <geometry>
        <mesh
        filename="package://hero_ros2/meshes/hero_7dof_arm_v2/raw/collada/link6.dae" />
      </geometry>
    </visual>
    <collision>
      <origin
        xyz="0 0 0"
        rpy="0 0 0" />
      <geometry>
        <mesh
        filename="package://hero_ros2/meshes/hero_7dof_arm_v2/raw/collada/link6.dae" />
      </geometry>
    </collision>
  </link>
  <joint
  name="leg202_joint6"
    type="continuous">
    <origin
      xyz="0 -0.0535 -0.067"
    rpy="-1.5708 -1.5707963267948966 0" />
    <parent
    link="leg202_link5" />
    <child
    link="leg202_link6" />
    <axis
      xyz="0 0 -1" />
    <limit
      lower="-9999"
      upper="9999"
      effort="9999"
      velocity="0.2" />
  </joint>
  <link
  name="leg202_link7">
  </link>
  <joint
  name="leg202_joint7"
    type="continuous">
    <origin
      xyz="0 0.067 -0.077"
      rpy="-1.5708 0 0" />
    <parent
    link="leg202_link6" />
    <child
    link="leg202_link7" />
    <axis
      xyz="0 0 1" />
    <limit
      lower="-9999"
      upper="9999"
      effort="9999"
      velocity="0.2" />
  </joint>
  <link
  name="leg202_gripper2_base">
    <inertial>
      <origin
        xyz="-7.1201E-05 -0.00037469 -0.034494"
        rpy="0 0 0" />
      <mass
        value="1.14" />
      <inertia
        ixx="0.00052757"
        ixy="-4.0284E-07"
        ixz="5.0575E-07"
        iyy="0.00020858"
        iyz="1.162E-07"
        izz="0.0007085" />
    </inertial>
    <visual>
      <origin
        xyz="0 0 0"
        rpy="0 0 0" />
      <geometry>
        <mesh
        filename="package://hero_ros2/meshes/hero_7dof_arm_v2/raw/collada/gripper2_base.dae" />
      </geometry>
    </visual>
    <collision>
      <isaac_sim>
        <attribute name="physics:approximation" value="sdf" />
      </isaac_sim>
      <origin
        xyz="0 0 0"
        rpy="0 0 0" />
      <geometry>
        <mesh
        filename="package://hero_ros2/meshes/hero_7dof_arm_v2/collision/gripper2_base.stl" />
      </geometry>
    </collision>
  </link>
  <joint
  name="leg202_gripper2_base_joint"
    type="fixed">
    <origin
      xyz="0 0 -0.0035001"
      rpy="3.1416 0 0" />
    <parent
    link="leg202_link7" />
    <child
    link="leg202_gripper2_base" />
  </joint>
  <link
  name="leg202_gripper2_jaw_left">
    <inertial>
      <origin
        xyz="-0.028778 0.020338 0.031675"
        rpy="0 0 0" />
      <mass
        value="0.33" />
      <inertia
        ixx="0.00015197"
        ixy="-1.8396E-05"
        ixz="9.6283E-06"
        iyy="0.00010778"
        iyz="-3.1239E-06"
        izz="0.00017771" />
    </inertial>
    <visual>
      <origin
        xyz="0 0 0"
        rpy="0 0 0" />
      <geometry>
        <mesh
        filename="package://hero_ros2/meshes/hero_7dof_arm_v2/raw/collada/gripper2_jaw_left.dae" />
      </geometry>
    </visual>
    <collision>
      <isaac_sim>
        <attribute name="physics:approximation" value="sdf" />
      </isaac_sim>
      <origin
        xyz="0 0 0"
        rpy="0 0 0" />
      <geometry>
        <mesh
        filename="package://hero_ros2/meshes/hero_7dof_arm_v2/collision/gripper2_jaw_left.stl" />
      </geometry>
    </collision>
  </link>
  <joint
  name="leg202_grip2"
    type="prismatic">
    <origin
      xyz="-0.035 -0.059 -0.05"
      rpy="3.1416 0 3.1416" />
    <parent
    link="leg202_gripper2_base" />
    <child
    link="leg202_gripper2_jaw_left" />
    <axis
      xyz="0 -1 0" />
    <limit
      lower="-0.05"
      upper="0.017"
      effort="9999"
      velocity="9999" />
    
    <isaac_sim>
      <attribute name="drive:linear:physics:maxForce" value="150000" />
      <attribute name="drive:linear:physics:damping" value="1000000.0"/>
      <attribute name="drive:linear:physics:stiffness" value="10000000.0"/>
    </isaac_sim>
  
  </joint>
  <link
  name="leg202_gripper2_jaw_right">
    <inertial>
      <origin
        xyz="-0.028779 0.020338 0.031675"
        rpy="0 0 0" />
      <mass
        value="0.33" />
      <inertia
        ixx="0.00015197"
        ixy="-1.8396E-05"
        ixz="9.6283E-06"
        iyy="0.00010778"
        iyz="-3.1239E-06"
        izz="0.00017771" />
    </inertial>
    <visual>
      <origin
        xyz="0 0 0"
        rpy="0 0 0" />
      <geometry>
        <mesh
        filename="package://hero_ros2/meshes/hero_7dof_arm_v2/raw/collada/gripper2_jaw_right.dae" />
      </geometry>
    </visual>
    <collision>
      <isaac_sim>
        <attribute name="physics:approximation" value="sdf" />
      </isaac_sim>
      <origin
        xyz="0 0 0"
        rpy="0 0 0" />
      <geometry>
        <mesh
        filename="package://hero_ros2/meshes/hero_7dof_arm_v2/collision/gripper2_jaw_right.stl" />
      </geometry>
    </collision>
  </link>
  <joint
  name="leg202_grip2bis"
    type="prismatic">
    <origin
      xyz="0.035 0.059 -0.05"
      rpy="3.1416 0 0" />
    <parent
    link="leg202_gripper2_base" />
    <child
    link="leg202_gripper2_jaw_right" />
    <axis
      xyz="0 1 0" />
    <limit
      lower="-0.05"
      upper="0.017"
      effort="9999"
      velocity="9999" />
    <mimic
    joint="leg202_grip2"
      multiplier="-1"
      offset="0" />
    
    <isaac_sim>
      <!-- Use low compliance mimic joint for the gripper -->
      <attribute name="physxMimicJoint:rotY:naturalFrequency" value="0.0" />
      <attribute name="physxMimicJoint:rotY:dampingRatio" value="0.005" />
    </isaac_sim>
  
  </joint>

    <link name="leg202_gripper2">
    </link>

    <joint name="leg202_gripper2_fixed_joint" type="fixed">
    <origin xyz="0 0 -0.065" rpy="0 1.5707963267948966 0" />
    <parent link="leg202_gripper2_base" />
    <child link="leg202_gripper2" />
    </joint>

    <link name="leg202_out_straight">
    </link>
    <joint name="leg202_gripper2_fix_to_straight" type="fixed">
    <origin xyz="0 0 0" rpy="1.5707963267948966 0 0" />
    <parent link="leg202_gripper2" />
    <child link="leg202_out_straight" />
    </joint>

  <link
  name="leg202_out">
  </link>
  <joint
  name="leg202_to_leaf"
    type="fixed">
    <origin
      xyz="0 0 -0.06"
    rpy="0 -0.0 -1.5707963267948966" />
    <parent
    link="leg202_gripper2_base" />
    <child
      link="leg202_out" />
  </joint>
<!-- </robot> -->
</robot>

